Traceback (most recent call last):
  File "/home/pi/workspace/autoHome2/loop.py", line 19, in <module>
    ser = serial.Serial('/dev/ttyUSB0',38400,timeout=1)
  File "/usr/local/lib/python2.7/dist-packages/serial/serialutil.py", line 182, in __init__
    self.open()
  File "/usr/local/lib/python2.7/dist-packages/serial/serialposix.py", line 247, in open
    raise SerialException(msg.errno, "could not open port {}: {}".format(self._port, msg))
serial.serialutil.SerialException: [Errno 2] could not open port /dev/ttyUSB0: [Errno 2] No such file or directory: '/dev/ttyUSB0'
